from django.core.exceptions import ValidationError
from rest_framework import serializers
from rest_framework.relations import SlugRelatedField
from rest_framework.validators import UniqueTogetherValidator

from posts.models import Comment, Post, Group, Follow, User

SELF_FOLLOW = 'Нельзя подписываться на себя!'


class PostSerializer(serializers.ModelSerializer):
    author = SlugRelatedField(slug_field='username', read_only=True)

    class Meta:
        fields = '__all__'
        model = Post


class GroupSerializer(serializers.ModelSerializer):
    class Meta:
        fields = '__all__'
        model = Group


class CommentSerializer(serializers.ModelSerializer):
    author = serializers.SlugRelatedField(
        read_only=True, slug_field='username'
    )

    class Meta:
        fields = '__all__'
        model = Comment


class FollowSerializer(serializers.ModelSerializer):
    user = serializers.SlugRelatedField(
        queryset=User.objects.all(),
        default=serializers.CurrentUserDefault(),
        slug_field='username'
    )
    following = serializers.SlugRelatedField(
        slug_field='username',
        queryset=User.objects.all()
    )

    class Meta:
        fields = '__all__'
        model = Follow
        validators = [
            UniqueTogetherValidator(
                queryset=Follow.objects.all(),
                fields=['user', 'following'],
                message=SELF_FOLLOW
            )
        ]

    def validate(self, data):
        if data['user'] == data['following']:
            raise ValidationError(SELF_FOLLOW)
        return data
